Workbook

Sheet Léeme
A1: Estructura inicial de contenido · IA generativa para entornos laborales
A2: Curso e-learning asincrónico · 88 h · 6 módulos · 22 aprendizajes esperados · diseño propio, PF1823 solo como referencia
A4: Qué es | B4: Estructura base del curso: módulo → competencia → aprendizaje esperado (AE) → contenidos (saber / saber hacer / saber ser) → técnica metodológica → recursos (Rise, quizzes, casos, hitos del proyecto, foro, videos, evaluaciones). Sirve de insumo para guiones de video, infografías y páginas de Rise.
A5: Audiencia | B5: Pensado para personas cesantes o en búsqueda de empleo como público principal, y que también sirva a quienes ya trabajan y quieren sumar IA. Un solo diseño para ambos: el proyecto parte de un «desafío laboral real», definido como una tarea de un cargo que la persona ejerce hoy o al que aspira (tomada de una oferta real). Los casos y ejemplos usan situaciones laborales comunes, sin suponer un empleo actual ni licencias corporativas: se priorizan herramientas gratuitas o con plan gratuito y uso desde celular. | C5: Solo en personas que estén trabajando. Está orientado a personas que usen IA en temas administrativos y de productividad en el trabajo.
A6: Normativa base | B6: RE 2.484 de 19-10-2026 (Instructivo FT), leída íntegra: ver hoja «Cumplimiento RE 2484», que cruza cada exigencia con este diseño. Importante: la RE remite los criterios, indicadores y medios de verificación de la evaluación técnica a un «Anexo Técnico» y a una «Guía Técnica» que NO vienen en el documento y que aún no están publicados en sence.cl. Mientras no los tengamos, no es posible asegurar la aprobación a la primera; ver «Pendientes».
A7: Estado | B7: BORRADOR de trabajo. Los 22 AE y las 6 competencias están diseñados para ser pertinentes a los módulos y temas de la propuesta a Accenture. PF1823 es solo una referencia: no se exige que coincidan con él. Aún NO se estructuró bajo la nueva normativa SENCE (RE 2.484): eso viene después, con el texto completo publicado.
A8: Modelo de tiempos | B8: 1 pantalla de Rise = 7,5 min · quiz formativo = 15 min por tema · foro = 30 min por módulo · videos de bienvenida y de resumen = 3 min cada uno · caso o hito de proyecto = 1,5 h. Todos son parámetros editables en la hoja «Parámetros»; el resto se recalcula.
A9: Criterio de diseño | B9: 1 tema = 1 AE = 1 Rise + 1 quiz formativo. Máximo 4 AE por módulo. Cada AE se trabaja en al menos un caso o hito del proyecto y se mide en la evaluación sumativa del módulo (ver columna «Cobertura» en «Estructura»).
A10: Proyecto incremental | B10: Un solo proyecto aplicado crece módulo a módulo (hitos P1 a P6d) y culmina en el pitch/portafolio. Cada hito tiene retroalimentación del facilitador/tutor responsable: es la instancia obligatoria de interacción, retroalimentación o acompañamiento que exigen la Ley 21.850 (art. 29 N°1) y la RE 2.484 (IV.2.1 g), además de la evaluación (IV.2.1 h).
A11: Casos de aplicación | B11: Los nombres de empresas son CANDIDATOS reales y públicos. Ninguno está verificado todavía: antes de guionar hay que localizar la fuente primaria, citarla con fecha y no usar cifras sin respaldo. No se inventan empresas, citas ni resultados.
A12: Hojas | B12: Parámetros · Resumen horas · Estructura · Matriz coherencia · Recursos · Casos y proyecto · Evaluación · Cumplimiento RE 2484 · Pendientes
A13: Convención de color | B13: Azul (letra) = dato que puedes editar. Negro = fórmula o texto fijo. Encabezados en azul #0090F8. | C13: Empoderatech.com

Sheet Parámetros
A1: Parámetros del modelo de tiempos
A2: Edita los valores en azul; todas las horas se recalculan.
A4: Parámetro | B4: Descripción | C4: Valor | D4: Unidad
A5: Minutos por pantalla Rise | B5: Lectura reflexiva de una pantalla | C5: 7.5 | D5: min
A6: Quiz formativo por tema | B6: Duración de cada quiz automatizado | C6: 15 | D6: min
A7: Foro por módulo | B7: Participación guiada con tutor | C7: 30 | D7: min
A8: Video de bienvenida | B8: Por módulo | C8: 3 | D8: min
A9: Video de resumen | B9: Por módulo | C9: 3 | D9: min
A10: Caso o hito de proyecto | B10: Duración de cada bloque de aplicación | C10: 90 | D10: min
A11: Inducción + diagnóstica (M1) | B11: Inducción tecnológica-metodológica, guía del participante y evaluación diagnóstica | C11: 45 | D11: min
A12: Horas totales del curso | B12: Según propuesta / plan formativo | C12: 88 | D12: h
A13: Tolerancia por módulo | B13: Diferencia aceptable entre horas objetivo y diseñadas | C13: 15 | D13: min

Sheet Resumen horas
A1: Resumen y coherencia de horas por módulo (desglose horario)
A2: La RE 2.484 (IV.2.2 c) exige concordancia entre la duración total y el desglose horario. Todo en minutos, calculado desde «Recursos»; la diferencia debe ser 0.
A4: Módulo | B4: Nombre | C4: Horas objetivo | D4: Min objetivo | E4: Min Rise | F4: Min Quiz formativo | G4: Min Caso de aplicación | H4: Min Hito proyecto | I4: Min Foro | J4: Min Video | K4: Min Evaluación sumativa | L4: Min Inducción/Diagnóstica | M4: Min Resumen y glosario | N4: Min diseñados | O4: Diferencia (min) | P4: Pantallas Rise | Q4: N° AE | R4: ¿Coherente?
A5: 1 | B5: Introducción a la IA generativa y prompt básico | C5: 16 | D5: =C5*60 -> 960 | E5: =SUMIFS(Recursos!$G$5:$G$105,Recursos!$B$5:$B$105,$A5,Recursos!$D$5:$D$105,"Rise") -> 487.5 | F5: =SUMIFS(Recursos!$G$5:$G$105,Recursos!$B$5:$B$105,$A5,Recursos!$D$5:$D$105,"Quiz formativo") -> 60 | G5: =SUMIFS(Recursos!$G$5:$G$105,Recursos!$B$5:$B$105,$A5,Recursos!$D$5:$D$105,"Caso de aplicación") -> 180 | H5: =SUMIFS(Recursos!$G$5:$G$105,Recursos!$B$5:$B$105,$A5,Recursos!$D$5:$D$105,"Hito proyecto") -> 90 | I5: =SUMIFS(Recursos!$G$5:$G$105,Recursos!$B$5:$B$105,$A5,Recursos!$D$5:$D$105,"Foro") -> 30 | J5: =SUMIFS(Recursos!$G$5:$G$105,Recursos!$B$5:$B$105,$A5,Recursos!$D$5:$D$105,"Video") -> 6 | K5: =SUMIFS(Recursos!$G$5:$G$105,Recursos!$B$5:$B$105,$A5,Recursos!$D$5:$D$105,"Evaluación sumativa") -> 60 | L5: =SUMIFS(Recursos!$G$5:$G$105,Recursos!$B$5:$B$105,$A5,Recursos!$D$5:$D$105,"Inducción/Diagnóstica") -> 45 | M5: =SUMIFS(Recursos!$G$5:$G$105,Recursos!$B$5:$B$105,$A5,Recursos!$D$5:$D$105,"Resumen y glosario") -> 1.5 | N5: =SUM(E5:M5) -> 960 | O5: =D5-N5 -> 0 | P5: =SUMIFS(Estructura!$M$5:$M$26,Estructura!$B$5:$B$26,A5) -> 65 | Q5: =COUNTIFS(Estructura!$B$5:$B$26,A5) -> 4 | R5: =IF(AND(ROUND(O5,1)=0,Q5<=4),"OK","Revisar") -> OK
A6: 2 | B6: Comunicación y redacción profesional | C6: 16 | D6: =C6*60 -> 960 | E6: =SUMIFS(Recursos!$G$5:$G$105,Recursos!$B$5:$B$105,$A6,Recursos!$D$5:$D$105,"Rise") -> 532.5 | F6: =SUMIFS(Recursos!$G$5:$G$105,Recursos!$B$5:$B$105,$A6,Recursos!$D$5:$D$105,"Quiz formativo") -> 60 | G6: =SUMIFS(Recursos!$G$5:$G$105,Recursos!$B$5:$B$105,$A6,Recursos!$D$5:$D$105,"Caso de aplicación") -> 180 | H6: =SUMIFS(Recursos!$G$5:$G$105,Recursos!$B$5:$B$105,$A6,Recursos!$D$5:$D$105,"Hito proyecto") -> 90 | I6: =SUMIFS(Recursos!$G$5:$G$105,Recursos!$B$5:$B$105,$A6,Recursos!$D$5:$D$105,"Foro") -> 30 | J6: =SUMIFS(Recursos!$G$5:$G$105,Recursos!$B$5:$B$105,$A6,Recursos!$D$5:$D$105,"Video") -> 6 | K6: =SUMIFS(Recursos!$G$5:$G$105,Recursos!$B$5:$B$105,$A6,Recursos!$D$5:$D$105,"Evaluación sumativa") -> 60 | L6: =SUMIFS(Recursos!$G$5:$G$105,Recursos!$B$5:$B$105,$A6,Recursos!$D$5:$D$105,"Inducción/Diagnóstica") -> 0 | M6: =SUMIFS(Recursos!$G$5:$G$105,Recursos!$B$5:$B$105,$A6,Recursos!$D$5:$D$105,"Resumen y glosario") -> 1.5 | N6: =SUM(E6:M6) -> 960 | O6: =D6-N6 -> 0 | P6: =SUMIFS(Estructura!$M$5:$M$26,Estructura!$B$5:$B$26,A6) -> 71 | Q6: =COUNTIFS(Estructura!$B$5:$B$26,A6) -> 4 | R6: =IF(AND(ROUND(O6,1)=0,Q6<=4),"OK","Revisar") -> OK
A7: 3 | B7: Investigación y análisis de información | C7: 16 | D7: =C7*60 -> 960 | E7: =SUMIFS(Recursos!$G$5:$G$105,Recursos!$B$5:$B$105,$A7,Recursos!$D$5:$D$105,"Rise") -> 532.5 | F7: =SUMIFS(Recursos!$G$5:$G$105,Recursos!$B$5:$B$105,$A7,Recursos!$D$5:$D$105,"Quiz formativo") -> 60 | G7: =SUMIFS(Recursos!$G$5:$G$105,Recursos!$B$5:$B$105,$A7,Recursos!$D$5:$D$105,"Caso de aplicación") -> 180 | H7: =SUMIFS(Recursos!$G$5:$G$105,Recursos!$B$5:$B$105,$A7,Recursos!$D$5:$D$105,"Hito proyecto") -> 90 | I7: =SUMIFS(Recursos!$G$5:$G$105,Recursos!$B$5:$B$105,$A7,Recursos!$D$5:$D$105,"Foro") -> 30 | J7: =SUMIFS(Recursos!$G$5:$G$105,Recursos!$B$5:$B$105,$A7,Recursos!$D$5:$D$105,"Video") -> 6 | K7: =SUMIFS(Recursos!$G$5:$G$105,Recursos!$B$5:$B$105,$A7,Recursos!$D$5:$D$105,"Evaluación sumativa") -> 60 | L7: =SUMIFS(Recursos!$G$5:$G$105,Recursos!$B$5:$B$105,$A7,Recursos!$D$5:$D$105,"Inducción/Diagnóstica") -> 0 | M7: =SUMIFS(Recursos!$G$5:$G$105,Recursos!$B$5:$B$105,$A7,Recursos!$D$5:$D$105,"Resumen y glosario") -> 1.5 | N7: =SUM(E7:M7) -> 960 | O7: =D7-N7 -> 0 | P7: =SUMIFS(Estructura!$M$5:$M$26,Estructura!$B$5:$B$26,A7) -> 71 | Q7: =COUNTIFS(Estructura!$B$5:$B$26,A7) -> 4 | R7: =IF(AND(ROUND(O7,1)=0,Q7<=4),"OK","Revisar") -> OK
A8: 4 | B8: Contenido visual, sonoro y audiovisual | C8: 16 | D8: =C8*60 -> 960 | E8: =SUMIFS(Recursos!$G$5:$G$105,Recursos!$B$5:$B$105,$A8,Recursos!$D$5:$D$105,"Rise") -> 442.5 | F8: =SUMIFS(Recursos!$G$5:$G$105,Recursos!$B$5:$B$105,$A8,Recursos!$D$5:$D$105,"Quiz formativo") -> 60 | G8: =SUMIFS(Recursos!$G$5:$G$105,Recursos!$B$5:$B$105,$A8,Recursos!$D$5:$D$105,"Caso de aplicación") -> 270 | H8: =SUMIFS(Recursos!$G$5:$G$105,Recursos!$B$5:$B$105,$A8,Recursos!$D$5:$D$105,"Hito proyecto") -> 90 | I8: =SUMIFS(Recursos!$G$5:$G$105,Recursos!$B$5:$B$105,$A8,Recursos!$D$5:$D$105,"Foro") -> 30 | J8: =SUMIFS(Recursos!$G$5:$G$105,Recursos!$B$5:$B$105,$A8,Recursos!$D$5:$D$105,"Video") -> 6 | K8: =SUMIFS(Recursos!$G$5:$G$105,Recursos!$B$5:$B$105,$A8,Recursos!$D$5:$D$105,"Evaluación sumativa") -> 60 | L8: =SUMIFS(Recursos!$G$5:$G$105,Recursos!$B$5:$B$105,$A8,Recursos!$D$5:$D$105,"Inducción/Diagnóstica") -> 0 | M8: =SUMIFS(Recursos!$G$5:$G$105,Recursos!$B$5:$B$105,$A8,Recursos!$D$5:$D$105,"Resumen y glosario") -> 1.5 | N8: =SUM(E8:M8) -> 960 | O8: =D8-N8 -> 0 | P8: =SUMIFS(Estructura!$M$5:$M$26,Estructura!$B$5:$B$26,A8) -> 59 | Q8: =COUNTIFS(Estructura!$B$5:$B$26,A8) -> 4 | R8: =IF(AND(ROUND(O8,1)=0,Q8<=4),"OK","Revisar") -> OK
A9: 5 | B9: Automatización de tareas repetitivas | C9: 12 | D9: =C9*60 -> 720 | E9: =SUMIFS(Recursos!$G$5:$G$105,Recursos!$B$5:$B$105,$A9,Recursos!$D$5:$D$105,"Rise") -> 322.5 | F9: =SUMIFS(Recursos!$G$5:$G$105,Recursos!$B$5:$B$105,$A9,Recursos!$D$5:$D$105,"Quiz formativo") -> 45 | G9: =SUMIFS(Recursos!$G$5:$G$105,Recursos!$B$5:$B$105,$A9,Recursos!$D$5:$D$105,"Caso de aplicación") -> 180 | H9: =SUMIFS(Recursos!$G$5:$G$105,Recursos!$B$5:$B$105,$A9,Recursos!$D$5:$D$105,"Hito proyecto") -> 90 | I9: =SUMIFS(Recursos!$G$5:$G$105,Recursos!$B$5:$B$105,$A9,Recursos!$D$5:$D$105,"Foro") -> 30 | J9: =SUMIFS(Recursos!$G$5:$G$105,Recursos!$B$5:$B$105,$A9,Recursos!$D$5:$D$105,"Video") -> 6 | K9: =SUMIFS(Recursos!$G$5:$G$105,Recursos!$B$5:$B$105,$A9,Recursos!$D$5:$D$105,"Evaluación sumativa") -> 45 | L9: =SUMIFS(Recursos!$G$5:$G$105,Recursos!$B$5:$B$105,$A9,Recursos!$D$5:$D$105,"Inducción/Diagnóstica") -> 0 | M9: =SUMIFS(Recursos!$G$5:$G$105,Recursos!$B$5:$B$105,$A9,Recursos!$D$5:$D$105,"Resumen y glosario") -> 1.5 | N9: =SUM(E9:M9) -> 720 | O9: =D9-N9 -> 0 | P9: =SUMIFS(Estructura!$M$5:$M$26,Estructura!$B$5:$B$26,A9) -> 43 | Q9: =COUNTIFS(Estructura!$B$5:$B$26,A9) -> 3 | R9: =IF(AND(ROUND(O9,1)=0,Q9<=4),"OK","Revisar") -> OK
A10: 6 | B10: Taller de IA generativa para entornos laborales | C10: 12 | D10: =C10*60 -> 720 | E10: =SUMIFS(Recursos!$G$5:$G$105,Recursos!$B$5:$B$105,$A10,Recursos!$D$5:$D$105,"Rise") -> 217.5 | F10: =SUMIFS(Recursos!$G$5:$G$105,Recursos!$B$5:$B$105,$A10,Recursos!$D$5:$D$105,"Quiz formativo") -> 45 | G10: =SUMIFS(Recursos!$G$5:$G$105,Recursos!$B$5:$B$105,$A10,Recursos!$D$5:$D$105,"Caso de aplicación") -> 0 | H10: =SUMIFS(Recursos!$G$5:$G$105,Recursos!$B$5:$B$105,$A10,Recursos!$D$5:$D$105,"Hito proyecto") -> 360 | I10: =SUMIFS(Recursos!$G$5:$G$105,Recursos!$B$5:$B$105,$A10,Recursos!$D$5:$D$105,"Foro") -> 30 | J10: =SUMIFS(Recursos!$G$5:$G$105,Recursos!$B$5:$B$105,$A10,Recursos!$D$5:$D$105,"Video") -> 6 | K10: =SUMIFS(Recursos!$G$5:$G$105,Recursos!$B$5:$B$105,$A10,Recursos!$D$5:$D$105,"Evaluación sumativa") -> 60 | L10: =SUMIFS(Recursos!$G$5:$G$105,Recursos!$B$5:$B$105,$A10,Recursos!$D$5:$D$105,"Inducción/Diagnóstica") -> 0 | M10: =SUMIFS(Recursos!$G$5:$G$105,Recursos!$B$5:$B$105,$A10,Recursos!$D$5:$D$105,"Resumen y glosario") -> 1.5 | N10: =SUM(E10:M10) -> 720 | O10: =D10-N10 -> 0 | P10: =SUMIFS(Estructura!$M$5:$M$26,Estructura!$B$5:$B$26,A10) -> 29 | Q10: =COUNTIFS(Estructura!$B$5:$B$26,A10) -> 3 | R10: =IF(AND(ROUND(O10,1)=0,Q10<=4),"OK","Revisar") -> OK
A11: Total | C11: =SUM(C5:C10) -> 88 | D11: =SUM(D5:D10) -> 5280 | E11: =SUM(E5:E10) -> 2535 | F11: =SUM(F5:F10) -> 330 | G11: =SUM(G5:G10) -> 990 | H11: =SUM(H5:H10) -> 810 | I11: =SUM(I5:I10) -> 180 | J11: =SUM(J5:J10) -> 36 | ... Q11: =SUM(Q5:Q10) -> 22 | R11: =IF(AND(C11='Parámetros'!$C$12,COUNTIF(R5:R10,"OK")=6),"OK","Revisar") -> OK
A13: Distribución del tiempo por tipo de actividad (total curso)
A14: Tipo | C14: Horas | D14: % del total
A15: Rise | C15: =E11/60 -> 42.25 | D15: =C15/'Parámetros'!$C$12 -> 0.48011364
A16: Quiz formativo | C16: =F11/60 -> 5.5 | D16: =C16/'Parámetros'!$C$12 -> 0.0625
A17: Caso de aplicación | C17: =G11/60 -> 16.5 | D17: =C17/'Parámetros'!$C$12 -> 0.1875
A18: Hito proyecto | C18: =H11/60 -> 13.5 | D18: =C18/'Parámetros'!$C$12 -> 0.15340909
A19: Foro | C19: =I11/60 -> 3 | D19: =C19/'Parámetros'!$C$12 -> 0.034090909
A20: Video | C20: =J11/60 -> 0.6 | D20: =C20/'Parámetros'!$C$12 -> 0.0068181818
A21: Evaluación sumativa | C21: =K11/60 -> 5.75 | D21: =C21/'Parámetros'!$C$12 -> 0.065340909
A22: Inducción/Diagnóstica | C22: =L11/60 -> 0.75 | D22: =C22/'Parámetros'!$C$12 -> 0.0085227273
A23: Resumen y glosario | C23: =M11/60 -> 0.15 | D23: =C23/'Parámetros'!$C$12 -> 0.0017045455
A24: Total | C24: =SUM(C15:C23) -> 88 | D24: =SUM(D15:D23) -> 1
A26: Lectura: el tiempo se reparte entre estudio en Rise (≈48%) y aplicación con casos e hitos del proyecto (≈34%); el resto son quizzes, foros, videos y evaluaciones. El desglose suma exactamente las 88 h.

Sheet Estructura
A1: Estructura: módulo → competencia → aprendizaje esperado → contenidos → recursos
A2: Un AE por tema. Verbo de aplicación + objeto + condición. Ascenso taxonómico dentro de cada módulo. Diseño propio, pertinente a cada módulo y tema (PF1823 solo como referencia).
A4: ID AE | B4: Módulo | C4: Nombre del módulo | D4: Competencia del módulo | E4: Tema (propuesta) | F4: Aprendizaje esperado | G4: Nivel taxonómico (Bloom) | H4: Saber (conocimientos) | I4: Saber hacer (habilidades) | J4: Saber ser (actitudes) | K4: Técnica metodológica | L4: Rise asociado | M4: Pantallas Rise | N4: Min Rise | O4: Quiz formativo (15 min) | P4: N° Rise | Q4: N° Quiz | R4: N° Casos/Hitos | S4: N° Evaluaciones | T4: Cobertura
A5: M1-AE1 | B5: 1 | C5: Introducción a la IA generativa y prompt básico | D5: Interactuar con modelos de IA generativa mediante prompts efectivos y validación de resultados, para apoyar tareas de oficina de forma verificada. | E5: Fundamentos de IA generativa | F5: Explicar el funcionamiento general, los tipos y los límites de la IA generativa, ejemplificando sus usos en tareas laborales cotidianas. | G5: Comprender | H5: Qué es IA generativa; modelos de lenguaje, imagen y audio; tokens y contexto; límites (alucinación, sesgo, fecha de corte). | I5: Distinguir qué tareas laborales conviene o no delegar a un modelo generativo; probar un asistente con una tarea simple. | J5: Curiosidad crítica; apertura a un uso responsable de la tecnología. | K5: Exposición interactiva en Rise + ejemplos guiados | L5: Rise M1-T1 · Fundamentos de IA generativa | M5: 16 | N5: =M5*'Parámetros'!$C$5 -> 120 | O5: 8 ítems: conceptos, tipos de modelo y límites (opción múltiple, V/F con justificación) | P5: =COUNTIFS(Recursos!$F$5:$F$200,"*"&A5&"*",Recursos!$D$5:$D$200,"Rise") -> 1 | Q5: =COUNTIFS(Recursos!$F$5:$F$200,"*"&A5&"*",Recursos!$D$5:$D$200,"Quiz formativo") -> 1 | R5: =COUNTIFS(Recursos!$F$5:$F$200,"*"&A5&"*",Recursos!$D$5:$D$200,"Caso de aplicación")+COUNTIFS(Recursos!$F$5:$F$200,"*"&A5&"*",Recursos!$D$5:$D$200,"Hito proyecto") -> 1 | S5: =COUNTIFS(Recursos!$F$5:$F$200,"*"&A5&"*",Recursos!$D$5:$D$200,"Evaluación sumativa") -> 1 | T5: =IF(AND(P5>=1,Q5>=1,R5>=1,S5>=1),"OK","Revisar") -> OK
A6: M1-AE2 | B6: 1 | C6: Introducción a la IA generativa y prompt básico | D6: Interactuar con modelos de IA generativa mediante prompts efectivos y validación de resultados, para apoyar tareas de oficina de forma verificada. | E6: Prompts efectivos | F6: Formular prompts efectivos con rol, contexto, tarea y formato para obtener respuestas útiles en tareas laborales simples. | G6: Aplicar | H6: Estructura de un prompt (rol, contexto, tarea, formato, restricciones); errores frecuentes; iteración. | I6: Redactar y refinar prompts para resumir, reescribir y clasificar información de oficina; armar una biblioteca personal de prompts. | J6: Perseverancia en la iteración; orden y documentación del propio trabajo. | K6: Práctica guiada con ejemplos antes/después + laboratorio de prompts | L6: Rise M1-T2 · Prompts efectivos | M6: 16 | N6: =M6*'Parámetros'!$C$5 -> 120 | O6: 8 ítems: identificar componentes, ordenar pasos, elegir el mejor prompt entre variantes | P6: =COUNTIFS(Recursos!$F$5:$F$200,"*"&A6&"*",Recursos!$D$5:$D$200,"Rise") -> 1 | Q6: =COUNTIFS(Recursos!$F$5:$F$200,"*"&A6&"*",Recursos!$D$5:$D$200,"Quiz formativo") -> 1 | R6: =COUNTIFS(Recursos!$F$5:$F$200,"*"&A6&"*",Recursos!$D$5:$D$200,"Caso de aplicación")+COUNTIFS(Recursos!$F$5:$F$200,"*"&A6&"*",Recursos!$D$5:$D$200,"Hito proyecto") -> 2 | S6: =COUNTIFS(Recursos!$F$5:$F$200,"*"&A6&"*",Recursos!$D$5:$D$200,"Evaluación sumativa") -> 1 | T6: =IF(AND(P6>=1,Q6>=1,R6>=1,S6>=1),"OK","Revisar") -> OK
A7: M1-AE3 | B7: 1 | C7: Introducción a la IA generativa y prompt básico | D7: Interactuar con modelos de IA generativa mediante prompts efectivos y validación de resultados, para apoyar tareas de oficina de forma verificada. | E7: Parámetros de generación | F7: Ajustar parámetros de generación (temperatura, longitud, iteración) para adecuar las respuestas a distintos objetivos de una tarea. | G7: Aplicar | H7: Parámetros de generación y su efecto; relación creatividad–precisión; configuración según tarea. | I7: Comparar salidas de un mismo prompt con distintos parámetros y seleccionar la configuración más adecuada. | J7: Rigor al comparar y registrar resultados. | K7: Experimentación guiada (comparación de salidas) | L7: Rise M1-T3 · Parámetros de generación | M7: 16 | N7: =M7*'Parámetros'!$C$5 -> 120 | O7: 8 ítems: elegir parámetro según objetivo, interpretar salidas comparadas | P7: =COUNTIFS(Recursos!$F$5:$F$200,"*"&A7&"*",Recursos!$D$5:$D$200,"Rise") -> 1 | Q7: =COUNTIFS(Recursos!$F$5:$F$200,"*"&A7&"*",Recursos!$D$5:$D$200,"Quiz formativo") -> 1 | R7: =COUNTIFS(Recursos!$F$5:$F$200,"*"&A7&"*",Recursos!$D$5:$D$200,"Caso de aplicación")+COUNTIFS(Recursos!$F$5:$F$200,"*"&A7&"*",Recursos!$D$5:$D$200,"Hito proyecto") -> 1 | S7: =COUNTIFS(Recursos!$F$5:$F$200,"*"&A7&"*",Recursos!$D$5:$D$200,"Evaluación sumativa") -> 1 | T7: =IF(AND(P7>=1,Q7>=1,R7>=1,S7>=1),"OK","Revisar") -> OK
A8: M1-AE4 | B8: 1 | C8: Introducción a la IA generativa y prompt básico | D8: Interactuar con modelos de IA generativa mediante prompts efectivos y validación de resultados, para apoyar tareas de oficina de forma verificada. | E8: Validación de resultados | F8: Validar resultados generados por IA, contrastándolos con fuentes confiables, para detectar alucinaciones, errores y sesgos. | G8: Evaluar | H8: Tipos de error (alucinación, sesgo, desactualización); criterios de confiabilidad de fuentes; checklist de validación. | I8: Aplicar un checklist de validación a respuestas generadas y corregir o descartar lo no verificable. | J8: Responsabilidad profesional sobre lo que se firma o comparte; honestidad intelectual. | K8: Aprendizaje basado en casos reales (errores documentados) | L8: Rise M1-T4 · Validación de resultados | M8: 17 | N8: =M8*'Parámetros'!$C$5 -> 127.5 | O8: 8 ítems: detectar errores en respuestas dadas, decidir qué verificar y cómo | P8: =COUNTIFS(Recursos!$F$5:$F$200,"*"&A8&"*",Recursos!$D$5:$D$200,"Rise") -> 1 | Q8: =COUNTIFS(Recursos!$F$5:$F$200,"*"&A8&"*",Recursos!$D$5:$D$200,"Quiz formativo") -> 1 | R8: =COUNTIFS(Recursos!$F$5:$F$200,"*"&A8&"*",Recursos!$D$5:$D$200,"Caso de aplicación")+COUNTIFS(Recursos!$F$5:$F$200,"*"&A8&"*",Recursos!$D$5:$D$200,"Hito proyecto") -> 1 | S8: =COUNTIFS(Recursos!$F$5:$F$200,"*"&A8&"*",Recursos!$D$5:$D$200,"Evaluación sumativa") -> 1 | T8: =IF(AND(P8>=1,Q8>=1,R8>=1,S8>=1),"OK","Revisar") -> OK
A9: M2-AE1 | B9: 2 | C9: Comunicación y redacción profesional | D9: Optimizar la elaboración de documentos, presentaciones y planillas de cálculo con IA generativa, cuidando tono, audiencia y exactitud, en contextos laborales. | E9: Redacción y comunicación con IA | F9: Redactar correos, minutas e informes con apoyo de IA, ajustando tono, registro y audiencia. | G9: Aplicar | H9: Géneros de comunicación laboral; tono, registro y audiencia; rol de la IA como borrador. | I9: Producir y ajustar un correo, una minuta y un informe ejecutivo con IA, adaptando el mensaje a distintas audiencias. | J9: Cortesía y claridad en la comunicación profesional; responsabilidad sobre el mensaje. | K9: Práctica guiada con casos de comunicación laboral | L9: Rise M2-T1 · Redacción y comunicación con IA | M9: 18 | N9: =M9*'Parámetros'!$C$5 -> 135 | O9: 8 ítems: elegir tono/registro según audiencia, corregir borradores | P9: =COUNTIFS(Recursos!$F$5:$F$200,"*"&A9&"*",Recursos!$D$5:$D$200,"Rise") -> 1 | Q9: =COUNTIFS(Recursos!$F$5:$F$200,"*"&A9&"*",Recursos!$D$5:$D$200,"Quiz formativo") -> 1 | R9: =COUNTIFS(Recursos!$F$5:$F$200,"*"&A9&"*",Recursos!$D$5:$D$200,"Caso de aplicación")+COUNTIFS(Recursos!$F$5:$F$200,"*"&A9&"*",Recursos!$D$5:$D$200,"Hito proyecto") -> 2 | S9: =COUNTIFS(Recursos!$F$5:$F$200,"*"&A9&"*",Recursos!$D$5:$D$200,"Evaluación sumativa") -> 1 | T9: =IF(AND(P9>=1,Q9>=1,R9>=1,S9>=1),"OK","Revisar") -> OK
A10: M2-AE2 | B10: 2 | C10: Comunicación y redacción profesional | D10: Optimizar la elaboración de documentos, presentaciones y planillas de cálculo con IA generativa, cuidando tono, audiencia y exactitud, en contextos laborales. | E10: Prompting avanzado para textos | F10: Aplicar técnicas de prompting avanzado (ejemplos, restricciones, encadenamiento) para mejorar la calidad y consistencia de textos profesionales. | G10: Aplicar | H10: Few-shot, restricciones de estilo, encadenamiento de pasos, plantillas reutilizables. | I10: Diseñar plantillas de prompts reutilizables para comunicación profesional y evaluar su consistencia. | J10: Orden metodológico; mejora continua del propio proceso. | K10: Laboratorio de prompts con comparación de versiones | L10: Rise M2-T2 · Prompting avanzado para textos | M10: 18 | N10: =M10*'Parámetros'!$C$5 -> 135 | O10: 8 ítems: seleccionar técnica según problema, completar plantillas | P10: =COUNTIFS(Recursos!$F$5:$F$200,"*"&A10&"*",Recursos!$D$5:$D$200,"Rise") -> 1 | Q10: =COUNTIFS(Recursos!$F$5:$F$200,"*"&A10&"*",Recursos!$D$5:$D$200,"Quiz formativo") -> 1 | R10: =COUNTIFS(Recursos!$F$5:$F$200,"*"&A10&"*",Recursos!$D$5:$D$200,"Caso de aplicación")+COUNTIFS(Recursos!$F$5:$F$200,"*"&A10&"*",Recursos!$D$5:$D$200,"Hito proyecto") -> 1 | S10: =COUNTIFS(Recursos!$F$5:$F$200,"*"&A10&"*",Recursos!$D$5:$D$200,"Evaluación sumativa") -> 1 | T10: =IF(AND(P10>=1,Q10>=1,R10>=1,S10>=1),"OK","Revisar") -> OK
A11: M2-AE3 | B11: 2 | C11: Comunicación y redacción profesional | D11: Optimizar la elaboración de documentos, presentaciones y planillas de cálculo con IA generativa, cuidando tono, audiencia y exactitud, en contextos laborales. | E11: Presentaciones con IA | F11: Estructurar presentaciones de 6 láminas con apoyo de IA a partir de un mensaje clave y una audiencia definida. | G11: Aplicar | H11: Estructura narrativa de una presentación; relación mensaje–lámina; herramientas de IA para presentaciones. | I11: Generar esquema, contenido y guion de una presentación de 6 láminas y depurarla críticamente. | J11: Sentido de síntesis; cuidado de la imagen profesional. | K11: Taller práctico guiado (producto) | L11: Rise M2-T3 · Presentaciones con IA | M11: 17 | N11: =M11*'Parámetros'!$C$5 -> 127.5 | O11: 8 ítems: ordenar estructura narrativa, detectar láminas sobrecargadas | P11: =COUNTIFS(Recursos!$F$5:$F$200,"*"&A11&"*",Recursos!$D$5:$D$200,"Rise") -> 1 | Q11: =COUNTIFS(Recursos!$F$5:$F$200,"*"&A11&"*",Recursos!$D$5:$D$200,"Quiz formativo") -> 1 | R11: =COUNTIFS(Recursos!$F$5:$F$200,"*"&A11&"*",Recursos!$D$5:$D$200,"Caso de aplicación")+COUNTIFS(Recursos!$F$5:$F$200,"*"&A11&"*",Recursos!$D$5:$D$200,"Hito proyecto") -> 2 | S11: =COUNTIFS(Recursos!$F$5:$F$200,"*"&A11&"*",Recursos!$D$5:$D$200,"Evaluación sumativa") -> 1 | T11: =IF(AND(P11>=1,Q11>=1,R11>=1,S11>=1),"OK","Revisar") -> OK
A12: M2-AE4 | B12: 2 | C12: Comunicación y redacción profesional | D12: Optimizar la elaboración de documentos, presentaciones y planillas de cálculo con IA generativa, cuidando tono, audiencia y exactitud, en contextos laborales. | E12: Planillas de cálculo con IA | F12: Resolver análisis en planillas de cálculo con fórmulas generadas por IA, verificando su exactitud. | G12: Evaluar | H12: Fórmulas y funciones básicas; cómo pedir fórmulas a la IA; verificación con datos de prueba. | I12: Generar, aplicar y comprobar fórmulas, filtros y tablas con apoyo de IA en Sheets o Excel. | J12: Rigor numérico; desconfianza metódica ante resultados no comprobados. | K12: Resolución de problemas con datos de práctica | L12: Rise M2-T4 · Planillas de cálculo con IA | M12: 18 | N12: =M12*'Parámetros'!$C$5 -> 135 | O12: 8 ítems: interpretar fórmulas, detectar errores de referencia o de lógica | P12: =COUNTIFS(Recursos!$F$5:$F$200,"*"&A12&"*",Recursos!$D$5:$D$200,"Rise") -> 1 | Q12: =COUNTIFS(Recursos!$F$5:$F$200,"*"&A12&"*",Recursos!$D$5:$D$200,"Quiz formativo") -> 1 | R12: =COUNTIFS(Recursos!$F$5:$F$200,"*"&A12&"*",Recursos!$D$5:$D$200,"Caso de aplicación")+COUNTIFS(Recursos!$F$5:$F$200,"*"&A12&"*",Recursos!$D$5:$D$200,"Hito proyecto") -> 1 | S12: =COUNTIFS(Recursos!$F$5:$F$200,"*"&A12&"*",Recursos!$D$5:$D$200,"Evaluación sumativa") -> 1 | T12: =IF(AND(P12>=1,Q12>=1,R12>=1,S12>=1),"OK","Revisar") -> OK
A13: M3-AE1 | B13: 3 | C13: Investigación y análisis de información | D13: Acelerar la investigación y el análisis de información con herramientas de IA, validando fuentes y resguardando la privacidad, para apoyar decisiones laborales. | E13: Herramientas de IA para investigar | F13: Utilizar herramientas de IA para investigar (buscadores con citas, asistentes sobre fuentes propias) y levantar información sobre un problema de su sector. | G13: Aplicar | H13: Tipos de herramientas de investigación con IA; búsqueda con citas; trabajo sobre documentos propios. | I13: Plantear preguntas de investigación y levantar información con al menos dos herramientas distintas. | J13: Curiosidad y autonomía en la búsqueda. | K13: Práctica guiada con herramientas | L13: Rise M3-T1 · Herramientas de IA para investigar | M13: 18 | N13: =M13*'Parámetros'!$C$5 -> 135 | O13: 8 ítems: elegir herramienta según necesidad, formular buenas preguntas | P13: =COUNTIFS(Recursos!$F$5:$F$200,"*"&A13&"*",Recursos!$D$5:$D$200,"Rise") -> 1 | Q13: =COUNTIFS(Recursos!$F$5:$F$200,"*"&A13&"*",Recursos!$D$5:$D$200,"Quiz formativo") -> 1 | R13: =COUNTIFS(Recursos!$F$5:$F$200,"*"&A13&"*",Recursos!$D$5:$D$200,"Caso de aplicación")+COUNTIFS(Recursos!$F$5:$F$200,"*"&A13&"*",Recursos!$D$5:$D$200,"Hito proyecto") -> 1 | S13: =COUNTIFS(Recursos!$F$5:$F$200,"*"&A13&"*",Recursos!$D$5:$D$200,"Evaluación sumativa") -> 1 | T13: =IF(AND(P13>=1,Q13>=1,R13>=1,S13>=1),"OK","Revisar") -> OK
A14: M3-AE2 | B14: 3 | C14: Investigación y análisis de información | D14: Acelerar la investigación y el análisis de información con herramientas de IA, validando fuentes y resguardando la privacidad, para apoyar decisiones laborales. | E14: Recopilar, validar y sintetizar | F14: Contrastar y sintetizar información de múltiples fuentes aplicando criterios de confiabilidad. | G14: Analizar | H14: Criterios de confiabilidad (autoría, fecha, respaldo); triangulación; técnicas de síntesis. | I14: Contrastar hallazgos entre fuentes, descartar los no respaldados y sintetizar lo verificado. | J14: Honestidad intelectual; respeto por la autoría. | K14: Análisis de fuentes con casos reales | L14: Rise M3-T2 · Recopilar, validar y sintetizar | M14: 18 | N14: =M14*'Parámetros'!$C$5 -> 135 | O14: 8 ítems: evaluar confiabilidad de fuentes, identificar contradicciones | P14: =COUNTIFS(Recursos!$F$5:$F$200,"*"&A14&"*",Recursos!$D$5:$D$200,"Rise") -> 1 | Q14: =COUNTIFS(Recursos!$F$5:$F$200,"*"&A14&"*",Recursos!$D$5:$D$200,"Quiz formativo") -> 1 | R14: =COUNTIFS(Recursos!$F$5:$F$200,"*"&A14&"*",Recursos!$D$5:$D$200,"Caso de aplicación")+COUNTIFS(Recursos!$F$5:$F$200,"*"&A14&"*",Recursos!$D$5:$D$200,"Hito proyecto") -> 1 | S14: =COUNTIFS(Recursos!$F$5:$F$200,"*"&A14&"*",Recursos!$D$5:$D$200,"Evaluación sumativa") -> 1 | T14: =IF(AND(P14>=1,Q14>=1,R14>=1,S14>=1),"OK","Revisar") -> OK
A15: M3-AE3 | B15: 3 | C15: Investigación y análisis de información | D15: Acelerar la investigación y el análisis de información con herramientas de IA, validando fuentes y resguardando la privacidad, para apoyar decisiones laborales. | E15: Organizar y presentar información | F15: Organizar y presentar hallazgos en un informe breve con fuentes citadas y mensajes clave. | G15: Aplicar | H15: Estructura de un informe breve; citación de fuentes; visualización simple de datos. | I15: Elaborar un informe breve de 1–2 páginas con hallazgos, fuentes y recomendaciones. | J15: Claridad y orden en la comunicación de resultados. | K15: Taller práctico (producto) | L15: Rise M3-T3 · Organizar y presentar información | M15: 17 | N15: =M15*'Parámetros'!$C$5 -> 127.5 | O15: 8 ítems: ordenar estructura del informe, corregir citas incompletas | P15: =COUNTIFS(Recursos!$F$5:$F$200,"*"&A15&"*",Recursos!$D$5:$D$200,"Rise") -> 1 | Q15: =COUNTIFS(Recursos!$F$5:$F$200,"*"&A15&"*",Recursos!$D$5:$D$200,"Quiz formativo") -> 1 | R15: =COUNTIFS(Recursos!$F$5:$F$200,"*"&A15&"*",Recursos!$D$5:$D$200,"Caso de aplicación")+COUNTIFS(Recursos!$F$5:$F$200,"*"&A15&"*",Recursos!$D$5:$D$200,"Hito proyecto") -> 1 | S15: =COUNTIFS(Recursos!$F$5:$F$200,"*"&A15&"*",Recursos!$D$5:$D$200,"Evaluación sumativa") -> 1 | T15: =IF(AND(P15>=1,Q15>=1,R15>=1,S15>=1),"OK","Revisar") -> OK
A16: M3-AE4 | B16: 3 | C16: Investigación y análisis de información | D16: Acelerar la investigación y el análisis de información con herramientas de IA, validando fuentes y resguardando la privacidad, para apoyar decisiones laborales. | E16: Análisis crítico y privacidad | F16: Evaluar críticamente los resultados de la IA y los riesgos de privacidad al usar información laboral, proponiendo prácticas de uso seguro. | G16: Evaluar | H16: Sesgos, trazabilidad y límites; datos personales y confidenciales; Ley 19.628 y políticas internas; buenas prácticas de uso seguro. | I16: Clasificar información según sensibilidad y decidir qué puede ingresar a una herramienta de IA. | J16: Responsabilidad y ética en el tratamiento de la información; confidencialidad. | K16: Aprendizaje basado en casos reales (incidentes documentados) | L16: Rise M3-T4 · Análisis crítico y privacidad | M16: 18 | N16: =M16*'Parámetros'!$C$5 -> 135 | O16: 8 ítems: clasificar datos por sensibilidad, decidir ante escenarios | P16: =COUNTIFS(Recursos!$F$5:$F$200,"*"&A16&"*",Recursos!$D$5:$D$200,"Rise") -> 1 | Q16: =COUNTIFS(Recursos!$F$5:$F$200,"*"&A16&"*",Recursos!$D$5:$D$200,"Quiz formativo") -> 1 | R16: =COUNTIFS(Recursos!$F$5:$F$200,"*"&A16&"*",Recursos!$D$5:$D$200,"Caso de aplicación")+COUNTIFS(Recursos!$F$5:$F$200,"*"&A16&"*",Recursos!$D$5:$D$200,"Hito proyecto") -> 2 | S16: =COUNTIFS(Recursos!$F$5:$F$200,"*"&A16&"*",Recursos!$D$5:$D$200,"Evaluación sumativa") -> 1 | T16: =IF(AND(P16>=1,Q16>=1,R16>=1,S16>=1),"OK","Revisar") -> OK
... A26: M6-AE3 | B26: 6 | C26: Taller de IA generativa para entornos laborales | D26: Aplicar la IA generativa en un proyecto basado en un desafío laboral real, midiendo resultados y comunicándolos, integrando lo aprendido en los módulos anteriores. | E26: Resultados y aprendizajes | F26: Evaluar los resultados del proyecto y comunicarlos mediante un pitch y un portafolio, proponiendo mejoras. | G26: Evaluar | H26: Medición de resultados; storytelling de resultados; estructura de pitch y portafolio. | I26: Medir resultados contra la línea base, elaborar el pitch y el portafolio, y proponer mejoras. | J26: Autocrítica constructiva; comunicación honesta de resultados, incluidos los límites. | K26: Proyecto aplicado con retroalimentación del tutor | L26: Rise M6-T3 · Resultados y aprendizajes | M26: 9 | N26: =M26*'Parámetros'!$C$5 -> 67.5 | O26: 8 ítems: interpretar resultados, ordenar estructura de un pitch | P26: =COUNTIFS(Recursos!$F$5:$F$200,"*"&A26&"*",Recursos!$D$5:$D$200,"Rise") -> 1 | Q26: =COUNTIFS(Recursos!$F$5:$F$200,"*"&A26&"*",Recursos!$D$5:$D$200,"Quiz formativo") -> 1 | R26: =COUNTIFS(Recursos!$F$5:$F$200,"*"&A26&"*",Recursos!$D$5:$D$200,"Caso de aplicación")+COUNTIFS(Recursos!$F$5:$F$200,"*"&A26&"*",Recursos!$D$5:$D$200,"Hito proyecto") -> 2 | S26: =COUNTIFS(Recursos!$F$5:$F$200,"*"&A26&"*",Recursos!$D$5:$D$200,"Evaluación sumativa") -> 1 | T26: =IF(AND(P26>=1,Q26>=1,R26>=1,S26>=1),"OK","Revisar") -> OK

Sheet Matriz coherencia
A1: Matriz de coherencia curricular
A2: RE 2.484 IV.2.2 b) y IV.3 a), b), c), f): competencia, AE, contenidos, técnicas, actividades, duración y evaluación deben ser coherentes entre sí.
A4: ID AE | B4: Módulo | C4: Competencia del módulo | D4: Aprendizaje esperado | E4: Bloom | F4: Contenidos (saber hacer) | G4: Técnica metodológica | H4: Actividades que lo trabajan | I4: Criterios de evaluación | J4: Instrumentos | K4: Min directos AE (Rise + quiz) | L4: Cobertura
A5: M1-AE1 | B5: 1 | C5: =Estructura!D5 -> Interactuar con modelos de IA generativa mediante prompts efectivos y validación de resultados, para apoyar tareas de oficina de forma verificada. | D5: =Estructura!F5 -> Explicar el funcionamiento general, los tipos y los límites de la IA generativa, ejemplificando sus usos en tareas laborales cotidianas. | E5: Comprender | F5: =Estructura!J5 -> Curiosidad crítica; apertura a un uso responsable de la tecnología. | G5: Exposición interactiva en Rise + ejemplos guiados | H5: Rise: Rise M1-T1 · Fundamentos de IA generativa; Foro M1; P1 (Hito proyecto) | I5: C1 Describe correctamente el funcionamiento y los tipos de IA generativa. C2 Ejemplifica al menos 3 usos y 2 límites en tareas laborales. | J5: Quiz formativo M1-AE1; Evaluación sumativa M1; Rúbrica P1; Evaluación final integradora | K5: =Estructura!N5+'Parámetros'!$C$6 -> 135 | L5: =Estructura!T5 -> OK
A6: M1-AE2 | B6: 1 | C6: =Estructura!D6 -> Interactuar con modelos de IA generativa mediante prompts efectivos y validación de resultados, para apoyar tareas de oficina de forma verificada. | D6: =Estructura!F6 -> Formular prompts efectivos con rol, contexto, tarea y formato para obtener respuestas útiles en tareas laborales simples. | E6: Aplicar | F6: =Estructura!J6 -> Perseverancia en la iteración; orden y documentación del propio trabajo. | G6: Práctica guiada con ejemplos antes/después + laboratorio de prompts | H6: Rise: Rise M1-T2 · Prompts efectivos; Foro M1; P1 (Hito proyecto); C1 (Caso de aplicación) | I6: C1 Incluye rol, contexto, tarea y formato en el prompt. C2 Obtiene una respuesta útil tras iterar al menos una vez. | J6: Quiz formativo M1-AE2; Evaluación sumativa M1; Rúbrica P1; Análisis de caso C1; Evaluación final integradora | K6: =Estructura!N6+'Parámetros'!$C$6 -> 135 | L6: =Estructura!T6 -> OK
A7: M1-AE3 | B7: 1 | C7: =Estructura!D7 -> Interactuar con modelos de IA generativa mediante prompts efectivos y validación de resultados, para apoyar tareas de oficina de forma verificada. | D7: =Estructura!F7 -> Ajustar parámetros de generación (temperatura, longitud, iteración) para adecuar las respuestas a distintos objetivos de una tarea. | E7: Aplicar | F7: =Estructura!J7 -> Rigor al comparar y registrar resultados. | G7: Experimentación guiada (comparación de salidas) | H7: Rise: Rise M1-T3 · Parámetros de generación; Foro M1; C1 (Caso de aplicación) | I7: C1 Elige un parámetro adecuado al objetivo y lo justifica. C2 Compara salidas de una misma consigna y selecciona la mejor con fundamento. | J7: Quiz formativo M1-AE3; Evaluación sumativa M1; Análisis de caso C1; Evaluación final integradora | K7: =Estructura!N7+'Parámetros'!$C$6 -> 135 | L7: =Estructura!T7 -> OK
A8: M1-AE4 | B8: 1 | C8: =Estructura!D8 -> Interactuar con modelos de IA generativa mediante prompts efectivos y validación de resultados, para apoyar tareas de oficina de forma verificada. | D8: =Estructura!F8 -> Validar resultados generados por IA, contrastándolos con fuentes confiables, para detectar alucinaciones, errores y sesgos. | E8: Evaluar | F8: =Estructura!J8 -> Responsabilidad profesional sobre lo que se firma o comparte; honestidad intelectual. | G8: Aprendizaje basado en casos reales (errores documentados) | H8: Rise: Rise M1-T4 · Validación de resultados; Foro M1; C2 (Caso de aplicación) | I8: C1 Identifica errores o sesgos en una respuesta generada. C2 Contrasta con al menos 2 fuentes confiables y corrige o descarta lo no verificable. | J8: Quiz formativo M1-AE4; Evaluación sumativa M1; Análisis de caso C2; Evaluación final integradora | K8: =Estructura!N8+'Parámetros'!$C$6 -> 142.5 | L8: =Estructura!T8 -> OK
A9: M2-AE1 | B9: 2 | C9: =Estructura!D9 -> Optimizar la elaboración de documentos, presentaciones y planillas de cálculo con IA generativa, cuidando tono, audiencia y exactitud, en contextos laborales. | D9: =Estructura!F9 -> Redactar correos, minutas e informes con apoyo de IA, ajustando tono, registro y audiencia. | E9: Aplicar | F9: =Estructura!J9 -> Cortesía y claridad en la comunicación profesional; responsabilidad sobre el mensaje. | G9: Práctica guiada con casos de comunicación laboral | H9: Rise: Rise M2-T1 · Redacción y comunicación con IA; Foro M2; P2 (Hito proyecto); C1 (Caso de aplicación) | I9: C1 Ajusta tono y registro a la audiencia indicada. C2 Entrega un texto claro y sin errores relevantes. | J9: Quiz formativo M2-AE1; Evaluación sumativa M2; Rúbrica P2; Análisis de caso C1; Evaluación final integradora | K9: =Estructura!N9+'Parámetros'!$C$6 -> 150 | L9: =Estructura!T9 -> OK
A10: M2-AE2 | B10: 2 | C10: =Estructura!D10 -> Optimizar la elaboración de documentos, presentaciones y planillas de cálculo con IA generativa, cuidando tono, audiencia y exactitud, en contextos laborales. | D10: =Estructura!F10 -> Aplicar técnicas de prompting avanzado (ejemplos, restricciones, encadenamiento) para mejorar la calidad y consistencia de textos profesionales. | E10: Aplicar | F10: =Estructura!J10 -> Orden metodológico; mejora continua del propio proceso. | G10: Laboratorio de prompts con comparación de versiones | H10: Rise: Rise M2-T2 · Prompting avanzado para textos; Foro M2; C1 (Caso de aplicación) | I10: C1 Aplica al menos dos técnicas (ejemplos, restricciones, encadenamiento). C2 Obtiene textos consistentes entre versiones. | J10: Quiz formativo M2-AE2; Evaluación sumativa M2; Análisis de caso C1; Evaluación final integradora | K10: =Estructura!N10+'Parámetros'!$C$6 -> 150 | L10: =Estructura!T10 -> OK
A11: M2-AE3 | B11: 2 | C11: =Estructura!D11 -> Optimizar la elaboración de documentos, presentaciones y planillas de cálculo con IA generativa, cuidando tono, audiencia y exactitud, en contextos laborales. | D11: =Estructura!F11 -> Estructurar presentaciones de 6 láminas con apoyo de IA a partir de un mensaje clave y una audiencia definida. | E11: Aplicar | F11: =Estructura!J11 -> Sentido de síntesis; cuidado de la imagen profesional. | G11: Taller práctico guiado (producto) | H11: Rise: Rise M2-T3 · Presentaciones con IA; Foro M2; P2 (Hito proyecto); C2 (Caso de aplicación) | I11: C1 Estructura 6 láminas con un mensaje clave coherente. C2 Depura el contenido generado (sobrecarga, errores). | J11: Quiz formativo M2-AE3; Evaluación sumativa M2; Rúbrica P2; Análisis de caso C2; Evaluación final integradora | K11: =Estructura!N11+'Parámetros'!$C$6 -> 142.5 | L11: =Estructura!T11 -> OK
A12: M2-AE4 | B12: 2 | C12: =Estructura!D12 -> Optimizar la elaboración de documentos, presentaciones y planillas de cálculo con IA generativa, cuidando tono, audiencia y exactitud, en contextos laborales. | D12: =Estructura!F12 -> Resolver análisis en planillas de cálculo con fórmulas generadas por IA, verificando su exactitud. | E12: Evaluar | F12: =Estructura!J12 -> Rigor numérico; desconfianza metódica ante resultados no comprobados. | G12: Resolución de problemas con datos de práctica | H12: Rise: Rise M2-T4 · Planillas de cálculo con IA; Foro M2; C2 (Caso de aplicación) | I12: C1 Genera una fórmula correcta para el problema planteado. C2 Comprueba el resultado con datos de prueba y corrige errores. | J12: Quiz formativo M2-AE4; Evaluación sumativa M2; Análisis de caso C2; Evaluación final integradora | K12: =Estructura!N12+'Parámetros'!$C$6 -> 150 | L12: =Estructura!T12 -> OK
A13: M3-AE1 | B13: 3 | C13: =Estructura!D13 -> Acelerar la investigación y el análisis de información con herramientas de IA, validando fuentes y resguardando la privacidad, para apoyar decisiones laborales. | D13: =Estructura!F13 -> Utilizar herramientas de IA para investigar (buscadores con citas, asistentes sobre fuentes propias) y levantar información sobre un problema de su sector. | E13: Aplicar | F13: =Estructura!J13 -> Curiosidad y autonomía en la búsqueda. | G13: Práctica guiada con herramientas | H13: Rise: Rise M3-T1 · Herramientas de IA para investigar; Foro M3; P3 (Hito proyecto) | I13: C1 Formula preguntas de investigación específicas. C2 Usa al menos 2 herramientas y registra las fuentes con su cita. | J13: Quiz formativo M3-AE1; Evaluación sumativa M3; Rúbrica P3; Evaluación final integradora | K13: =Estructura!N13+'Parámetros'!$C$6 -> 150 | L13: =Estructura!T13 -> OK
A14: M3-AE2 | B14: 3 | C14: =Estructura!D14 -> Acelerar la investigación y el análisis de información con herramientas de IA, validando fuentes y resguardando la privacidad, para apoyar decisiones laborales. | D14: =Estructura!F14 -> Contrastar y sintetizar información de múltiples fuentes aplicando criterios de confiabilidad. | E14: Analizar | F14: =Estructura!J14 -> Honestidad intelectual; respeto por la autoría. | G14: Análisis de fuentes con casos reales | H14: Rise: Rise M3-T2 · Recopilar, validar y sintetizar; Foro M3; C1 (Caso de aplicación) | I14: C1 Aplica criterios de confiabilidad (autoría, fecha, respaldo). C2 Sintetiza hallazgos contrastados sin afirmaciones sin respaldo. | J14: Quiz formativo M3-AE2; Evaluación sumativa M3; Análisis de caso C1; Evaluación final integradora | K14: =Estructura!N14+'Parámetros'!$C$6 -> 150 | L14: =Estructura!T14 -> OK
A15: M3-AE3 | B15: 3 | C15: =Estructura!D15 -> Acelerar la investigación y el análisis de información con herramientas de IA, validando fuentes y resguardando la privacidad, para apoyar decisiones laborales. | D15: =Estructura!F15 -> Organizar y presentar hallazgos en un informe breve con fuentes citadas y mensajes clave. | E15: Aplicar | F15: =Estructura!J15 -> Claridad y orden en la comunicación de resultados. | G15: Taller práctico (producto) | H15: Rise: Rise M3-T3 · Organizar y presentar información; Foro M3; P3 (Hito proyecto) | I15: C1 Organiza el informe con una estructura definida. C2 Cita todas las fuentes y formula recomendaciones. | J15: Quiz formativo M3-AE3; Evaluación sumativa M3; Rúbrica P3; Evaluación final integradora | K15: =Estructura!N15+'Parámetros'!$C$6 -> 142.5 | L15: =Estructura!T15 -> OK
A16: M3-AE4 | B16: 3 | C16: =Estructura!D16 -> Acelerar la investigación y el análisis de información con herramientas de IA, validando fuentes y resguardando la privacidad, para apoyar decisiones laborales. | D16: =Estructura!F16 -> Evaluar críticamente los resultados de la IA y los riesgos de privacidad al usar información laboral, proponiendo prácticas de uso seguro. | E16: Evaluar | F16: =Estructura!J16 -> Responsabilidad y ética en el tratamiento de la información; confidencialidad. | G16: Aprendizaje basado en casos reales (incidentes documentados) | H16: Rise: Rise M3-T4 · Análisis crítico y privacidad; Foro M3; C1 (Caso de aplicación); C2 (Caso de aplicación) | I16: C1 Clasifica la información según su sensibilidad. C2 Decide con fundamento qué puede ingresar a una herramienta de IA y propone una práctica segura. | J16: Quiz formativo M3-AE4; Evaluación sumativa M3; Análisis de caso C1; Análisis de caso C2; Evaluación final integradora | K16: =Estructura!N16+'Parámetros'!$C$6 -> 150 | L16: =Estructura!T16 -> OK
... A26: M6-AE3 | B26: 6 | C26: =Estructura!D26 -> Aplicar la IA generativa en un proyecto basado en un desafío laboral real, midiendo resultados y comunicándolos, integrando lo aprendido en los módulos anteriores. | D26: =Estructura!F26 -> Evaluar los resultados del proyecto y comunicarlos mediante un pitch y un portafolio, proponiendo mejoras. | E26: Evaluar | F26: =Estructura!J26 -> Autocrítica constructiva; comunicación honesta de resultados, incluidos los límites. | G26: Proyecto aplicado con retroalimentación del tutor | H26: Rise: Rise M6-T3 · Resultados y aprendizajes; Foro M6; P6c (Hito proyecto); P6d (Hito proyecto) | I26: C1 Compara los resultados con la línea base. C2 Comunica resultados y límites con claridad en un pitch de 3 minutos. | J26: Quiz formativo M6-AE3; Evaluación sumativa M6; Rúbrica P6c; Rúbrica P6d; Evaluación final integradora | K26: =Estructura!N26+'Parámetros'!$C$6 -> 82.5 | L26: =Estructura!T26 -> OK

Sheet Recursos
A1: Recursos por módulo (en orden de aprendizaje)
A2: Cada fila es un recurso producible. Duración en minutos calculada con los parámetros. Estado y responsable se editan.
A4: ID | B4: Módulo | C4: Orden | D4: Tipo | E4: Recurso / título | F4: AE que trabaja | G4: Duración (min) | H4: Cuenta en horas | I4: Interacción facilitador/tutor | J4: Formato / herramienta | K4: Responsable | L4: Archivo o guion | M4: Estado
A5: R001 | B5: 1 | C5: =COUNTIFS($B$5:B5,B5) -> 1 | D5: Inducción/Diagnóstica | E5: Inducción tecnológica-metodológica (video) + Guía del participante + Evaluación diagnóstica | F5: — | G5: ='Parámetros'!$C$11 -> 45 | H5: Sí | I5: No | J5: Video + PDF + cuestionario | K5: Diseño instruccional | M5: Pendiente
A6: R002 | B6: 1 | C6: =COUNTIFS($B$5:B6,B6) -> 2 | D6: Video | E6: Video de bienvenida M1 (3 min): qué aprenderás, cómo se evalúa, hito del proyecto | F6: — | G6: ='Parámetros'!$C$8 -> 3 | H6: Sí | I6: No | J6: Video con avatar/locución | K6: Diseño instruccional | M6: Pendiente
A7: R003 | B7: 1 | C7: =COUNTIFS($B$5:B7,B7) -> 3 | D7: Rise | E7: Rise M1-T1 · Fundamentos de IA generativa | F7: M1-AE1 | G7: =Estructura!N5 -> 120 | H7: Sí | I7: No | J7: Rise (pantallas) | K7: Diseño instruccional | M7: Pendiente
A8: R004 | B8: 1 | C8: =COUNTIFS($B$5:B8,B8) -> 4 | D8: Quiz formativo | E8: Quiz formativo M1-AE1 · Fundamentos de IA generativa | F8: M1-AE1 | G8: ='Parámetros'!$C$6 -> 15 | H8: Sí | I8: No | J8: Quiz automatizado con retroalimentación + acción remedial | K8: Diseño instruccional | M8: Pendiente
A9: R005 | B9: 1 | C9: =COUNTIFS($B$5:B9,B9) -> 5 | D9: Rise | E9: Rise M1-T2 · Prompts efectivos | F9: M1-AE2 | G9: =Estructura!N6 -> 120 | H9: Sí | I9: No | J9: Rise (pantallas) | K9: Diseño instruccional | M9: Pendiente
A10: R006 | B10: 1 | C10: =COUNTIFS($B$5:B10,B10) -> 6 | D10: Quiz formativo | E10: Quiz formativo M1-AE2 · Prompts efectivos | F10: M1-AE2 | G10: ='Parámetros'!$C$6 -> 15 | H10: Sí | I10: No | J10: Quiz automatizado con retroalimentación + acción remedial | K10: Diseño instruccional | M10: Pendiente
A11: R007 | B11: 1 | C11: =COUNTIFS($B$5:B11,B11) -> 7 | D11: Rise | E11: Rise M1-T3 · Parámetros de generación | F11: M1-AE3 | G11: =Estructura!N7 -> 120 | H11: Sí | I11: No | J11: Rise (pantallas) | K11: Diseño instruccional | M11: Pendiente
A12: R008 | B12: 1 | C12: =COUNTIFS($B$5:B12,B12) -> 8 | D12: Quiz formativo | E12: Quiz formativo M1-AE3 · Parámetros de generación | F12: M1-AE3 | G12: ='Parámetros'!$C$6 -> 15 | H12: Sí | I12: No | J12: Quiz automatizado con retroalimentación + acción remedial | K12: Diseño instruccional | M12: Pendiente
A13: R009 | B13: 1 | C13: =COUNTIFS($B$5:B13,B13) -> 9 | D13: Rise | E13: Rise M1-T4 · Validación de resultados | F13: M1-AE4 | G13: =Estructura!N8 -> 127.5 | H13: Sí | I13: No | J13: Rise (pantallas) | K13: Diseño instruccional | M13: Pendiente
A14: R010 | B14: 1 | C14: =COUNTIFS($B$5:B14,B14) -> 10 | D14: Quiz formativo | E14: Quiz formativo M1-AE4 · Validación de resultados | F14: M1-AE4 | G14: ='Parámetros'!$C$6 -> 15 | H14: Sí | I14: No | J14: Quiz automatizado con retroalimentación + acción remedial | K14: Diseño instruccional | M14: Pendiente
A15: R011 | B15: 1 | C15: =COUNTIFS($B$5:B15,B15) -> 11 | D15: Hito proyecto | E15: Proyecto aplicado · Hito 1: problema u oportunidad real + biblioteca de prompts v1 | F15: M1-AE1; M1-AE2 | G15: ='Parámetros'!$C$10 -> 90 | H15: Sí | I15: Sí | J15: Rise + actividad (caso) / entrega con rúbrica (hito) | K15: Diseño instruccional | M15: Pendiente
A16: R012 | B16: 1 | C16: =COUNTIFS($B$5:B16,B16) -> 12 | D16: Caso de aplicación | E16: Caso M1-C1 · Asistente de IA para asesores financieros (Morgan Stanley) | F16: M1-AE2; M1-AE3 | G16: ='Parámetros'!$C$10 -> 90 | H16: Sí | I16: No | J16: Rise + actividad (caso) / entrega con rúbrica (hito) | K16: Diseño instruccional | M16: Pendiente
A17: R013 | B17: 1 | C17: =COUNTIFS($B$5:B17,B17) -> 13 | D17: Caso de aplicación | E17: Caso M1-C2 · Cuando la IA inventa: abogados y jurisprudencia inexistente (Mata v. Avianca, 2023) y chatbot de Air Canada (2024) | F17: M1-AE4 | G17: ='Parámetros'!$C$10 -> 90 | H17: Sí | I17: No | J17: Rise + actividad (caso) / entrega con rúbrica (hito) | K17: Diseño instruccional | M17: Pendiente
A18: R014 | B18: 1 | C18: =COUNTIFS($B$5:B18,B18) -> 14 | D18: Foro | E18: Foro M1: discusión guiada del módulo (tutor responde en <24 h hábiles) | F18: M1-AE1; M1-AE2; M1-AE3; M1-AE4 | G18: ='Parámetros'!$C$7 -> 30 | H18: Sí | I18: Sí | J18: Foro Moodle | K18: Diseño instruccional | M18: Pendiente
A19: R015 | B19: 1 | C19: =COUNTIFS($B$5:B19,B19) -> 15 | D19: Video | E19: Video de resumen M1 (3 min): ideas clave y conexión con el siguiente módulo | F19: — | G19: ='Parámetros'!$C$9 -> 3 | H19: Sí | I19: No | J19: Video con avatar/locución | K19: Diseño instruccional | M19: Pendiente
A20: R016 | B20: 1 | C20: =COUNTIFS($B$5:B20,B20) -> 16 | D20: Resumen y glosario | E20: Resumen y glosario del módulo M1 (página; lectura 1,5 min) | F20: — | G20: 1.5 | H20: Sí | I20: No | J20: Página Moodle | K20: Diseño instruccional | M20: Pendiente
A21: R017 | B21: 1 | C21: =COUNTIFS($B$5:B21,B21) -> 17 | D21: Complemento | E21: Infografía M1: Anatomía de un prompt efectivo (rol · contexto · tarea · formato) | F21: — | G21: 0 | H21: No | I21: No | J21: Infografía (imagen) | K21: Diseño instruccional | M21: Pendiente
A22: R018 | B22: 1 | C22: =COUNTIFS($B$5:B22,B22) -> 18 | D22: Evaluación sumativa | E22: Evaluación sumativa M1 | F22: M1-AE1; M1-AE2; M1-AE3; M1-AE4 | G22: 60 | H22: Sí | I22: No | J22: Cuestionario Moodle con retroalimentación automática | K22: Diseño instruccional | M22: Pendiente
A23: R019 | B23: 2 | C23: =COUNTIFS($B$5:B23,B23) -> 1 | D23: Video | E23: Video de bienvenida M2 (3 min): qué aprenderás, cómo se evalúa, hito del proyecto | F23: — | G23: ='Parámetros'!$C$8 -> 3 | H23: Sí | I23: No | J23: Video con avatar/locución | K23: Diseño instruccional | M23: Pendiente
A24: R020 | B24: 2 | C24: =COUNTIFS($B$5:B24,B24) -> 2 | D24: Rise | E24: Rise M2-T1 · Redacción y comunicación con IA | F24: M2-AE1 | G24: =Estructura!N9 -> 135 | H24: Sí | I24: No | J24: Rise (pantallas) | K24: Diseño instruccional | M24: Pendiente
A25: R021 | B25: 2 | C25: =COUNTIFS($B$5:B25,B25) -> 3 | D25: Quiz formativo | E25: Quiz formativo M2-AE1 · Redacción y comunicación con IA | F25: M2-AE1 | G25: ='Parámetros'!$C$6 -> 15 | H25: Sí | I25: No | J25: Quiz automatizado con retroalimentación + acción remedial | K25: Diseño instruccional | M25: Pendiente
A26: R022 | B26: 2 | C26: =COUNTIFS($B$5:B26,B26) -> 4 | D26: Rise | E26: Rise M2-T2 · Prompting avanzado para textos | F26: M2-AE2 | G26: =Estructura!N10 -> 135 | H26: Sí | I26: No | J26: Rise (pantallas) | K26: Diseño instruccional | M26: Pendiente
A27: R023 | B27: 2 | C27: =COUNTIFS($B$5:B27,B27) -> 5 | D27: Quiz formativo | E27: Quiz formativo M2-AE2 · Prompting avanzado para textos | F27: M2-AE2 | G27: ='Parámetros'!$C$6 -> 15 | H27: Sí | I27: No | J27: Quiz automatizado con retroalimentación + acción remedial | K27: Diseño instruccional | M27: Pendiente
A28: R024 | B28: 2 | C28: =COUNTIFS($B$5:B28,B28) -> 6 | D28: Rise | E28: Rise M2-T3 · Presentaciones con IA | F28: M2-AE3 | G28: =Estructura!N11 -> 127.5 | H28: Sí | I28: No | J28: Rise (pantallas) | K28: Diseño instruccional | M28: Pendiente
A29: R025 | B29: 2 | C29: =COUNTIFS($B$5:B29,B29) -> 7 | D29: Quiz formativo | E29: Quiz formativo M2-AE3 · Presentaciones con IA | F29: M2-AE3 | G29: ='Parámetros'!$C$6 -> 15 | H29: Sí | I29: No | J29: Quiz automatizado con retroalimentación + acción remedial | K29: Diseño instruccional | M29: Pendiente
A30: R026 | B30: 2 | C30: =COUNTIFS($B$5:B30,B30) -> 8 | D30: Rise | E30: Rise M2-T4 · Planillas de cálculo con IA | F30: M2-AE4 | G30: =Estructura!N12 -> 135 | H30: Sí | I30: No | J30: Rise (pantallas) | K30: Diseño instruccional | M30: Pendiente
A31: R027 | B31: 2 | C31: =COUNTIFS($B$5:B31,B31) -> 9 | D31: Quiz formativo | E31: Quiz formativo M2-AE4 · Planillas de cálculo con IA | F31: M2-AE4 | G31: ='Parámetros'!$C$6 -> 15 | H31: Sí | I31: No | J31: Quiz automatizado con retroalimentación + acción remedial | K31: Diseño instruccional | M31: Pendiente
A32: R028 | B32: 2 | C32: =COUNTIFS($B$5:B32,B32) -> 10 | D32: Hito proyecto | E32: Proyecto aplicado · Hito 2: brief del proyecto + presentación de 6 láminas | F32: M2-AE1; M2-AE3 | G32: ='Parámetros'!$C$10 -> 90 | H32: Sí | I32: Sí | J32: Rise + actividad (caso) / entrega con rúbrica (hito) | K32: Diseño instruccional | M32: Pendiente
A33: R029 | B33: 2 | C33: =COUNTIFS($B$5:B33,B33) -> 11 | D33: Caso de aplicación | E33: Caso M2-C1 · Comunicación con clientes redactada con apoyo de IA (Octopus Energy) | F33: M2-AE1; M2-AE2 | G33: ='Parámetros'!$C$10 -> 90 | H33: Sí | I33: No | J33: Rise + actividad (caso) / entrega con rúbrica (hito) | K33: Diseño instruccional | M33: Pendiente
A34: R030 | B34: 2 | C34: =COUNTIFS($B$5:B34,B34) -> 12 | D34: Caso de aplicación | E34: Caso M2-C2 · Asistente de IA en herramientas de oficina para equipos (Vodafone y Microsoft 365 Copilot) | F34: M2-AE3; M2-AE4 | G34: ='Parámetros'!$C$10 -> 90 | H34: Sí | I34: No | J34: Rise + actividad (caso) / entrega con rúbrica (hito) | K34: Diseño instruccional | M34: Pendiente
A35: R031 | B35: 2 | C35: =COUNTIFS($B$5:B35,B35) -> 13 | D35: Foro | E35: Foro M2: discusión guiada del módulo (tutor responde en <24 h hábiles) | F35: M2-AE1; M2-AE2; M2-AE3; M2-AE4 | G35: ='Parámetros'!$C$7 -> 30 | H35: Sí | I35: Sí | J35: Foro Moodle | K35: Diseño instruccional | M35: Pendiente
A36: R032 | B36: 2 | C36: =COUNTIFS($B$5:B36,B36) -> 14 | D36: Video | E36: Video de resumen M2 (3 min): ideas clave y conexión con el siguiente módulo | F36: — | G36: ='Parámetros'!$C$9 -> 3 | H36: Sí | I36: No | J36: Video con avatar/locución | K36: Diseño instruccional | M36: Pendiente
A37: R033 | B37: 2 | C37: =COUNTIFS($B$5:B37,B37) -> 15 | D37: Resumen y glosario | E37: Resumen y glosario del módulo M2 (página; lectura 1,5 min) | F37: — | G37: 1.5 | H37: Sí | I37: No | J37: Página Moodle | K37: Diseño instruccional | M37: Pendiente
A38: R034 | B38: 2 | C38: =COUNTIFS($B$5:B38,B38) -> 16 | D38: Complemento | E38: Infografía M2: Flujo de redacción aumentada (borrador → ajuste → verificación) | F38: — | G38: 0 | H38: No | I38: No | J38: Infografía (imagen) | K38: Diseño instruccional | M38: Pendiente
A39: R035 | B39: 2 | C39: =COUNTIFS($B$5:B39,B39) -> 17 | D39: Evaluación sumativa | E39: Evaluación sumativa M2 | F39: M2-AE1; M2-AE2; M2-AE3; M2-AE4 | G39: 60 | H39: Sí | I39: No | J39: Cuestionario Moodle con retroalimentación automática | K39: Diseño instruccional | M39: Pendiente
A40: R036 | B40: 3 | C40: =COUNTIFS($B$5:B40,B40) -> 1 | D40: Video | E40: Video de bienvenida M3 (3 min): qué aprenderás, cómo se evalúa, hito del proyecto | F40: — | G40: ='Parámetros'!$C$8 -> 3 | H40: Sí | I40: No | J40: Video con avatar/locución | K40: Diseño instruccional | M40: Pendiente
A41: R037 | B41: 3 | C41: =COUNTIFS($B$5:B41,B41) -> 2 | D41: Rise | E41: Rise M3-T1 · Herramientas de IA para investigar | F41: M3-AE1 | G41: =Estructura!N13 -> 135 | H41: Sí | I41: No | J41: Rise (pantallas) | K41: Diseño instruccional | M41: Pendiente
...

Sheet Casos y proyecto
A1: Casos de aplicación e hitos del proyecto incremental
A2: Casos con empresas reales (candidatos por verificar) y el proyecto que crece módulo a módulo hasta el pitch final.
A4: ID | B4: Módulo | C4: Tipo | D4: Título | E4: AE | F4: Descripción / qué documentar | G4: Fuente primaria (URL, fecha) | H4: Estado de verificación | I4: Entregable | J4: Retroalimentación tutor
A5: M1-P1 | B5: 1 | C5: Hito proyecto | D5: Proyecto aplicado · Hito 1: problema u oportunidad real + biblioteca de prompts v1 | E5: M1-AE1; M1-AE2 | F5: Cada participante elige un desafío laboral real: una tarea de un cargo que ejerce o al que aspira (tomada de una oferta real) y arma su primera biblioteca de prompts para resolverla. Entregable con retroalimentación del tutor (≤72 h). | H5: No aplica | I5: Entrega con rúbrica general (ver «Evaluación») | J5: ≤72 h (hábiles a definir)
A6: M1-C1 | B6: 1 | C6: Caso de aplicación | D6: Caso M1-C1 · Asistente de IA para asesores financieros (Morgan Stanley) | E6: M1-AE2; M1-AE3 | F6: Candidato. Documentar: qué prompts/instrucciones se usan, qué fuentes consulta el asistente, cómo se controla la calidad. POR VERIFICAR en fuente primaria (comunicados de la empresa y de OpenAI). | H6: Por verificar | I6: Actividad de análisis del caso: preguntas guiadas + aplicación al proyecto (1,5 h) | J6: Autocorrección + foro
A7: M1-C2 | B7: 1 | C7: Caso de aplicación | D7: Caso M1-C2 · Cuando la IA inventa: abogados y jurisprudencia inexistente (Mata v. Avianca, 2023) y chatbot de Air Canada (2024) | E7: M1-AE4 | F7: Candidato. Documentar: qué se verificó o no, consecuencias. POR VERIFICAR en fuente primaria (resoluciones judiciales / del tribunal). | H7: Por verificar | I7: Actividad de análisis del caso: preguntas guiadas + aplicación al proyecto (1,5 h) | J7: Autocorrección + foro
A8: M2-P2 | B8: 2 | C8: Hito proyecto | D8: Proyecto aplicado · Hito 2: brief del proyecto + presentación de 6 láminas | E8: M2-AE1; M2-AE3 | F8: El problema del Hito 1 se convierte en un brief (objetivo, audiencia, mensaje) y una presentación de 6 láminas con IA. Retroalimentación del tutor (≤72 h). | H8: No aplica | I8: Entrega con rúbrica general (ver «Evaluación») | J8: ≤72 h (hábiles a definir)
A9: M2-C1 | B9: 2 | C9: Caso de aplicación | D9: Caso M2-C1 · Comunicación con clientes redactada con apoyo de IA (Octopus Energy) | E9: M2-AE1; M2-AE2 | F9: Candidato. Documentar el uso de IA para respuestas a clientes y cómo se supervisa. POR VERIFICAR en fuente primaria/prensa de calidad, con fecha. | H9: Por verificar | I9: Actividad de análisis del caso: preguntas guiadas + aplicación al proyecto (1,5 h) | J9: Autocorrección + foro
